<?xml version="1.0" ?>
<sdf version="1.10">

    <world name="car_world">

        <!-- Moving Forward -->
        <plugin filename="gz-sim-triggered-publisher-system"
                name="gz::sim::systems::TriggeredPublisher">
            <input type="gz.msgs.Int32" topic="/keyboard/keypress">
                <match field="data">87</match>
            </input>
            <output type="gz.msgs.Twist" topic="/cmd_vel">
                linear: {x: 0.5}, angular: {z: 0.0}
            </output>
        </plugin>

        <!-- Moving Backward -->
        <plugin filename="gz-sim-triggered-publisher-system"
                name="gz::sim::systems::TriggeredPublisher">
            <input type="gz.msgs.Int32" topic="/keyboard/keypress">
                <match field="data">83</match>
            </input>
            <output type="gz.msgs.Twist" topic="/cmd_vel">
                linear: {x: -0.5}, angular: {z: 0.0}
            </output>
        </plugin>

        <!-- Moving Right -->
        <plugin filename="gz-sim-triggered-publisher-system"
                name="gz::sim::systems::TriggeredPublisher">
            <input type="gz.msgs.Int32" topic="/keyboard/keypress">
                <match field="data">68</match>
            </input>
            <output type="gz.msgs.Twist" topic="/cmd_vel">
                linear: {x: 0.5}, angular: {z: 0.5}
            </output>
        </plugin>

        <!-- Moving Left -->
        <plugin filename="gz-sim-triggered-publisher-system"
                name="gz::sim::systems::TriggeredPublisher">
            <input type="gz.msgs.Int32" topic="/keyboard/keypress">
                <match field="data">65</match>
            </input>
            <output type="gz.msgs.Twist" topic="/cmd_vel">
                linear: {x: 0.5}, angular: {z: -0.5}
            </output>
        </plugin>

        <!-- Halt -->
        <plugin filename="gz-sim-triggered-publisher-system"
                name="gz::sim::systems::TriggeredPublisher">
            <input type="gz.msgs.Int32" topic="/keyboard/keypress">
                <match field="data">88</match>
            </input>
            <output type="gz.msgs.Twist" topic="/cmd_vel">
                linear: {x: 0.0}, angular: {z: 0.0}
            </output>
        </plugin>

        <physics name="1ms" type="ignored">
            <max_step_size>0.001</max_step_size>
            <real_time_factor>1.0</real_time_factor>
        </physics>

        <plugin filename="gz-sim-physics-system" name="gz::sim::systems::Physics"/>
        <plugin filename="gz-sim-user-commands-system" name="gz::sim::systems::UserCommands"/>
        <plugin filename="gz-sim-scene-broadcaster-system" name="gz::sim::systems::SceneBroadcaster"/>

        <light type="directional" name="sun">
            <cast_shadows>true</cast_shadows>
            <pose>0 0 10 0 0 0</pose>
            <diffuse>0.8 0.8 0.8 1</diffuse>
            <specular>0.2 0.2 0.2 1</specular>
            <attenuation>
                <range>1000</range>
                <constant>0.9</constant>
                <linear>0.01</linear>
                <quadratic>0.001</quadratic>
            </attenuation>
            <direction>-0.5 0.1 -0.9</direction>
        </light>

        <model name="ground_plane">
            <static>true</static>
            <link name="link">
                <collision name="collision">
                    <geometry>
                        <plane>
                            <normal>0 0 1</normal>
                        </plane>
                    </geometry>
                </collision>
                <visual name="visual">
                    <geometry>
                        <plane>
                            <normal>0 0 1</normal>
                            <size>100 100</size>
                        </plane>
                    </geometry>
                    <material>
                        <ambient>0.8 0.8 0.8 1</ambient>
                        <diffuse>0.8 0.8 0.8 1</diffuse>
                        <specular>0.8 0.8 0.8 1</specular>
                    </material>
                </visual>
            </link>
        </model>

        <model name="vehicle_blue" canonical_link="chassis">

            <plugin filename="gz-sim-diff-drive-system"
                    name="gz::sim::systems::DiffDrive">
                <left_joint>rear_left_wheel_joint</left_joint>
                <right_joint>rear_right_wheel_joint</right_joint>
                <wheel_separation>1.125</wheel_separation>
                <wheel_radius>0.15</wheel_radius>
                <odom_publish_frequency>1</odom_publish_frequency>
                <topic>cmd_vel</topic>
            </plugin>

            <pose relative_to="world">0 0 0 0 0 0</pose>

            <link name="chassis">
                <pose relative_to="__model__">0.5 0 0.4 0 0 0</pose>
                <inertial>
                    <mass>1.14395</mass>
                    <inertia>
                        <ixx>0.095329</ixx>
                        <ixy>0</ixy>
                        <ixz>0</ixz>
                        <iyy>0.381317</iyy>
                        <iyz>0</iyz>
                        <izz>0.476646</izz>
                    </inertia>
                </inertial>
                <visual name="visual">
                    <geometry>
                        <box>
                            <size>1.0 0.75 0.25</size>
                        </box>
                    </geometry>
                    <material>
                        <ambient>0.0 0.0 1.0 1</ambient>
                        <diffuse>0.0 0.0 1.0 1</diffuse>
                        <specular>0.0 0.0 1.0 1</specular>
                    </material>
                </visual>
                <collision name="collision">
                    <geometry>
                        <box>
                            <size>1.0 0.75 0.25</size>
                        </box>
                    </geometry>
                </collision>
            </link>

            <link name="wheel_rear_right">
                <pose relative_to="chassis">-0.375 +0.5625 -0.15 -1.5707 0 0</pose> <!--angles are in radian-->
                <inertial>
                    <mass>1</mass>
                    <inertia>
                        <ixx>0.043333</ixx>
                        <ixy>0</ixy>
                        <ixz>0</ixz>
                        <iyy>0.043333</iyy>
                        <iyz>0</iyz>
                        <izz>0.08</izz>
                    </inertia>
                </inertial>
                <visual name="visual">
                    <geometry>
                        <cylinder>
                            <radius>0.15</radius>
                            <length>0.125</length>
                        </cylinder>
                    </geometry>
                    <material>
                        <ambient>1.0 0.0 0.0 1</ambient>
                        <diffuse>1.0 0.0 0.0 1</diffuse>
                        <specular>1.0 0.0 0.0 1</specular>
                    </material>
                </visual>
                <collision name="collision">
                    <geometry>
                        <cylinder>
                            <radius>0.15</radius>
                            <length>0.125</length>
                        </cylinder>
                    </geometry>
                </collision>
            </link>

            <link name="wheel_rear_left">
                <pose relative_to="chassis">-0.375 -0.5625 -0.15 -1.5707 0 0</pose> <!--angles are in radian-->
                <inertial>
                    <mass>1</mass>
                    <inertia>
                        <ixx>0.043333</ixx>
                        <ixy>0</ixy>
                        <ixz>0</ixz>
                        <iyy>0.043333</iyy>
                        <iyz>0</iyz>
                        <izz>0.08</izz>
                    </inertia>
                </inertial>
                <visual name="visual">
                    <geometry>
                        <cylinder>
                            <radius>0.15</radius>
                            <length>0.125</length>
                        </cylinder>
                    </geometry>
                    <material>
                        <ambient>1.0 0.0 0.0 1</ambient>
                        <diffuse>1.0 0.0 0.0 1</diffuse>
                        <specular>1.0 0.0 0.0 1</specular>
                    </material>
                </visual>
                <collision name="collision">
                    <geometry>
                        <cylinder>
                            <radius>0.15</radius>
                            <length>0.125</length>
                        </cylinder>
                    </geometry>
                </collision>
            </link>

            <frame name="caster_left_frame" attached_to="chassis">
                <pose>0.375 -0.5625 -0.15 0 0 0</pose>
            </frame>

            <frame name="caster_right_frame" attached_to="chassis">
                <pose>0.375 0.5625 -0.15 0 0 0</pose>
            </frame>

            <!-- caster wheel -->
            <link name="caster_left">
                <pose relative_to="caster_left_frame"/>
                <inertial>
                    <mass>1</mass>
                    <inertia>
                        <ixx>0.016</ixx>
                        <ixy>0</ixy>
                        <ixz>0</ixz>
                        <iyy>0.016</iyy>
                        <iyz>0</iyz>
                        <izz>0.016</izz>
                    </inertia>
                </inertial>
                <collision name="collision">
                    <geometry>
                        <sphere>
                            <radius>0.15</radius>
                        </sphere>
                    </geometry>
                </collision>
            </link>

            <link name="caster_right">
                <pose relative_to="caster_right_frame"/>
                <inertial>
                    <mass>1</mass>
                    <inertia>
                        <ixx>0.016</ixx>
                        <ixy>0</ixy>
                        <ixz>0</ixz>
                        <iyy>0.016</iyy>
                        <iyz>0</iyz>
                        <izz>0.016</izz>
                    </inertia>
                </inertial>
                <collision name="collision">
                    <geometry>
                        <sphere>
                            <radius>0.15</radius>
                        </sphere>
                    </geometry>
                </collision>
            </link>

            <joint name="caster_left_joint" type="ball">
                <parent>chassis</parent>
                <child>caster_left</child>
            </joint>

            <joint name="caster_right_joint" type="ball">
                <parent>chassis</parent>
                <child>caster_right</child>
            </joint>

            <joint name="rear_right_wheel_joint" type="revolute">
                <pose relative_to="wheel_rear_right"/>
                <parent>chassis</parent>
                <child>wheel_rear_right</child>
                <axis>
                    <xyz expressed_in="__model__">0 1 0</xyz>
                    <limit>
                        <lower>-1.79769e+308</lower>    <!--negative infinity-->
                        <upper>1.79769e+308</upper>     <!--positive infinity-->
                    </limit>
                </axis>
            </joint>

            <joint name="rear_left_wheel_joint" type="revolute">
                <pose relative_to="wheel_rear_left"/>
                <parent>chassis</parent>
                <child>wheel_rear_left</child>
                <axis>
                    <xyz expressed_in="__model__">0 1 0</xyz>
                    <limit>
                        <lower>-1.79769e+308</lower>    <!--negative infinity-->
                        <upper>1.79769e+308</upper>     <!--positive infinity-->
                    </limit>
                </axis>
            </joint>

        </model>
    </world>
</sdf>
